[2025-05-04T06:32:49.308+0000] {logging_mixin.py:151} INFO - Changing /opt/airflow/logs/dag_id=statsbomb_full_ingestion/run_id=scheduled__2025-05-03T00:00:00+00:00/task_id=ingest_competitions permission to 509
[2025-05-04T06:32:49.398+0000] {logging_mixin.py:151} INFO - Changing /opt/airflow/logs/dag_id=statsbomb_full_ingestion/run_id=scheduled__2025-05-03T00:00:00+00:00/task_id=ingest_competitions permission to 509
[2025-05-04T06:32:49.445+0000] {taskinstance.py:1157} INFO - Dependencies all met for dep_context=non-requeueable deps ti=<TaskInstance: statsbomb_full_ingestion.ingest_competitions scheduled__2025-05-03T00:00:00+00:00 [queued]>
[2025-05-04T06:32:49.461+0000] {taskinstance.py:1157} INFO - Dependencies all met for dep_context=requeueable deps ti=<TaskInstance: statsbomb_full_ingestion.ingest_competitions scheduled__2025-05-03T00:00:00+00:00 [queued]>
[2025-05-04T06:32:49.463+0000] {taskinstance.py:1359} INFO - Starting attempt 1 of 2
[2025-05-04T06:32:49.483+0000] {taskinstance.py:1380} INFO - Executing <Task(PythonOperator): ingest_competitions> on 2025-05-03 00:00:00+00:00
[2025-05-04T06:32:49.491+0000] {standard_task_runner.py:57} INFO - Started process 1274 to run task
[2025-05-04T06:32:49.496+0000] {standard_task_runner.py:84} INFO - Running: ['airflow', 'tasks', 'run', 'statsbomb_full_ingestion', 'ingest_competitions', 'scheduled__2025-05-03T00:00:00+00:00', '--job-id', '42', '--raw', '--subdir', 'DAGS_FOLDER/statsbomb_ingestion.py', '--cfg-path', '/tmp/tmpcu99qk6o']
[2025-05-04T06:32:49.500+0000] {standard_task_runner.py:85} INFO - Job 42: Subtask ingest_competitions
[2025-05-04T06:32:49.569+0000] {logging_mixin.py:151} INFO - Changing /opt/airflow/logs/dag_id=statsbomb_full_ingestion/run_id=scheduled__2025-05-03T00:00:00+00:00/task_id=ingest_competitions permission to 509
[2025-05-04T06:32:49.587+0000] {task_command.py:415} INFO - Running <TaskInstance: statsbomb_full_ingestion.ingest_competitions scheduled__2025-05-03T00:00:00+00:00 [running]> on host db0a756e67ca
[2025-05-04T06:32:49.822+0000] {taskinstance.py:1660} INFO - Exporting env vars: AIRFLOW_CTX_DAG_OWNER='airflow' AIRFLOW_CTX_DAG_ID='statsbomb_full_ingestion' AIRFLOW_CTX_TASK_ID='ingest_competitions' AIRFLOW_CTX_EXECUTION_DATE='2025-05-03T00:00:00+00:00' AIRFLOW_CTX_TRY_NUMBER='1' AIRFLOW_CTX_DAG_RUN_ID='scheduled__2025-05-03T00:00:00+00:00'
[2025-05-04T06:32:49.824+0000] {statsbomb_ingestion.py:30} INFO - Downloading https://raw.githubusercontent.com/statsbomb/open-data/master/data/competitions.json
[2025-05-04T06:32:49.838+0000] {taskinstance.py:1935} ERROR - Task failed with exception
Traceback (most recent call last):
  File "/home/airflow/.local/lib/python3.8/site-packages/urllib3/connection.py", line 174, in _new_conn
    conn = connection.create_connection(
  File "/home/airflow/.local/lib/python3.8/site-packages/urllib3/util/connection.py", line 72, in create_connection
    for res in socket.getaddrinfo(host, port, family, socket.SOCK_STREAM):
  File "/usr/local/lib/python3.8/socket.py", line 918, in getaddrinfo
    for res in _socket.getaddrinfo(host, port, family, type, proto, flags):
socket.gaierror: [Errno -3] Temporary failure in name resolution

During handling of the above exception, another exception occurred:

Traceback (most recent call last):
  File "/home/airflow/.local/lib/python3.8/site-packages/urllib3/connectionpool.py", line 714, in urlopen
    httplib_response = self._make_request(
  File "/home/airflow/.local/lib/python3.8/site-packages/urllib3/connectionpool.py", line 403, in _make_request
    self._validate_conn(conn)
  File "/home/airflow/.local/lib/python3.8/site-packages/urllib3/connectionpool.py", line 1053, in _validate_conn
    conn.connect()
  File "/home/airflow/.local/lib/python3.8/site-packages/urllib3/connection.py", line 363, in connect
    self.sock = conn = self._new_conn()
  File "/home/airflow/.local/lib/python3.8/site-packages/urllib3/connection.py", line 186, in _new_conn
    raise NewConnectionError(
urllib3.exceptions.NewConnectionError: <urllib3.connection.HTTPSConnection object at 0x7fdfbe184af0>: Failed to establish a new connection: [Errno -3] Temporary failure in name resolution

During handling of the above exception, another exception occurred:

Traceback (most recent call last):
  File "/home/airflow/.local/lib/python3.8/site-packages/requests/adapters.py", line 486, in send
    resp = conn.urlopen(
  File "/home/airflow/.local/lib/python3.8/site-packages/urllib3/connectionpool.py", line 798, in urlopen
    retries = retries.increment(
  File "/home/airflow/.local/lib/python3.8/site-packages/urllib3/util/retry.py", line 592, in increment
    raise MaxRetryError(_pool, url, error or ResponseError(cause))
urllib3.exceptions.MaxRetryError: HTTPSConnectionPool(host='raw.githubusercontent.com', port=443): Max retries exceeded with url: /statsbomb/open-data/master/data/competitions.json (Caused by NewConnectionError('<urllib3.connection.HTTPSConnection object at 0x7fdfbe184af0>: Failed to establish a new connection: [Errno -3] Temporary failure in name resolution'))

During handling of the above exception, another exception occurred:

Traceback (most recent call last):
  File "/home/airflow/.local/lib/python3.8/site-packages/airflow/operators/python.py", line 192, in execute
    return_value = self.execute_callable()
  File "/home/airflow/.local/lib/python3.8/site-packages/airflow/operators/python.py", line 209, in execute_callable
    return self.python_callable(*self.op_args, **self.op_kwargs)
  File "/opt/airflow/dags/statsbomb_ingestion.py", line 49, in ingest_competitions
    fetch_and_upload(key="competitions.json", url=url)
  File "/opt/airflow/dags/statsbomb_ingestion.py", line 31, in fetch_and_upload
    resp = requests.get(url)
  File "/home/airflow/.local/lib/python3.8/site-packages/requests/api.py", line 73, in get
    return request("get", url, params=params, **kwargs)
  File "/home/airflow/.local/lib/python3.8/site-packages/requests/api.py", line 59, in request
    return session.request(method=method, url=url, **kwargs)
  File "/home/airflow/.local/lib/python3.8/site-packages/requests/sessions.py", line 589, in request
    resp = self.send(prep, **send_kwargs)
  File "/home/airflow/.local/lib/python3.8/site-packages/requests/sessions.py", line 703, in send
    r = adapter.send(request, **kwargs)
  File "/home/airflow/.local/lib/python3.8/site-packages/requests/adapters.py", line 519, in send
    raise ConnectionError(e, request=request)
requests.exceptions.ConnectionError: HTTPSConnectionPool(host='raw.githubusercontent.com', port=443): Max retries exceeded with url: /statsbomb/open-data/master/data/competitions.json (Caused by NewConnectionError('<urllib3.connection.HTTPSConnection object at 0x7fdfbe184af0>: Failed to establish a new connection: [Errno -3] Temporary failure in name resolution'))
[2025-05-04T06:32:49.874+0000] {taskinstance.py:1398} INFO - Marking task as UP_FOR_RETRY. dag_id=statsbomb_full_ingestion, task_id=ingest_competitions, execution_date=20250503T000000, start_date=20250504T063249, end_date=20250504T063249
[2025-05-04T06:32:49.903+0000] {standard_task_runner.py:104} ERROR - Failed to execute job 42 for task ingest_competitions (HTTPSConnectionPool(host='raw.githubusercontent.com', port=443): Max retries exceeded with url: /statsbomb/open-data/master/data/competitions.json (Caused by NewConnectionError('<urllib3.connection.HTTPSConnection object at 0x7fdfbe184af0>: Failed to establish a new connection: [Errno -3] Temporary failure in name resolution')); 1274)
[2025-05-04T06:32:49.923+0000] {local_task_job_runner.py:228} INFO - Task exited with return code 1
[2025-05-04T06:32:49.964+0000] {taskinstance.py:2776} INFO - 0 downstream tasks scheduled from follow-on schedule check
