[2025-05-05T10:03:05.672+0000] {logging_mixin.py:151} INFO - Changing /opt/airflow/logs/dag_id=statsbomb_full_ingestion/run_id=scheduled__2025-05-04T00:00:00+00:00/task_id=ingest_matches permission to 509
[2025-05-05T10:03:05.851+0000] {logging_mixin.py:151} INFO - Changing /opt/airflow/logs/dag_id=statsbomb_full_ingestion/run_id=scheduled__2025-05-04T00:00:00+00:00/task_id=ingest_matches permission to 509
[2025-05-05T10:03:05.930+0000] {taskinstance.py:1157} INFO - Dependencies all met for dep_context=non-requeueable deps ti=<TaskInstance: statsbomb_full_ingestion.ingest_matches scheduled__2025-05-04T00:00:00+00:00 [queued]>
[2025-05-05T10:03:05.955+0000] {taskinstance.py:1157} INFO - Dependencies all met for dep_context=requeueable deps ti=<TaskInstance: statsbomb_full_ingestion.ingest_matches scheduled__2025-05-04T00:00:00+00:00 [queued]>
[2025-05-05T10:03:05.957+0000] {taskinstance.py:1359} INFO - Starting attempt 3 of 2
[2025-05-05T10:03:06.004+0000] {taskinstance.py:1380} INFO - Executing <Task(PythonOperator): ingest_matches> on 2025-05-04 00:00:00+00:00
[2025-05-05T10:03:06.017+0000] {standard_task_runner.py:57} INFO - Started process 217 to run task
[2025-05-05T10:03:06.040+0000] {standard_task_runner.py:84} INFO - Running: ['airflow', 'tasks', 'run', 'statsbomb_full_ingestion', 'ingest_matches', 'scheduled__2025-05-04T00:00:00+00:00', '--job-id', '51', '--raw', '--subdir', 'DAGS_FOLDER/statsbomb_ingestion.py', '--cfg-path', '/tmp/tmp8r9xdyoq']
[2025-05-05T10:03:06.063+0000] {standard_task_runner.py:85} INFO - Job 51: Subtask ingest_matches
[2025-05-05T10:03:10.365+0000] {logging_mixin.py:151} INFO - Changing /opt/airflow/logs/dag_id=statsbomb_full_ingestion/run_id=scheduled__2025-05-04T00:00:00+00:00/task_id=ingest_matches permission to 509
[2025-05-05T10:03:13.158+0000] {task_command.py:415} INFO - Running <TaskInstance: statsbomb_full_ingestion.ingest_matches scheduled__2025-05-04T00:00:00+00:00 [running]> on host d081a19c8154
[2025-05-05T10:03:19.066+0000] {taskinstance.py:1660} INFO - Exporting env vars: AIRFLOW_CTX_DAG_OWNER='airflow' AIRFLOW_CTX_DAG_ID='statsbomb_full_ingestion' AIRFLOW_CTX_TASK_ID='ingest_matches' AIRFLOW_CTX_EXECUTION_DATE='2025-05-04T00:00:00+00:00' AIRFLOW_CTX_TRY_NUMBER='3' AIRFLOW_CTX_DAG_RUN_ID='scheduled__2025-05-04T00:00:00+00:00'
[2025-05-05T10:03:19.549+0000] {statsbomb_ingestion.py:30} INFO - Downloading https://raw.githubusercontent.com/statsbomb/open-data/master/data/matches/9/281.json
[2025-05-05T10:03:20.113+0000] {crypto.py:82} WARNING - empty cryptography key - values will not be stored encrypted.
[2025-05-05T10:03:20.846+0000] {base.py:73} INFO - Using connection ID 'minio_default' for task execution.
[2025-05-05T10:03:21.385+0000] {logging_mixin.py:151} WARNING - <string>:8 AirflowProviderDeprecationWarning: AWS Connection (conn_id='minio_default', conn_type='s3') has connection type 's3', which has been replaced by connection type 'aws'. Please update your connection to have `conn_type='aws'`.
[2025-05-05T10:03:22.082+0000] {connection_wrapper.py:340} INFO - AWS Connection (conn_id='minio_default', conn_type='s3') credentials retrieved from login and password.
[2025-05-05T10:03:22.442+0000] {logging_mixin.py:151} WARNING - <string>:8 AirflowProviderDeprecationWarning: Host minio specified in the connection is not used. Please, set it on extra['endpoint_url'] instead
[2025-05-05T10:09:07.535+0000] {job.py:219} ERROR - Job heartbeat got an exception
Traceback (most recent call last):
  File "/home/airflow/.local/lib/python3.8/site-packages/sqlalchemy/engine/base.py", line 3371, in _wrap_pool_connect
    return fn()
  File "/home/airflow/.local/lib/python3.8/site-packages/sqlalchemy/pool/base.py", line 327, in connect
    return _ConnectionFairy._checkout(self)
  File "/home/airflow/.local/lib/python3.8/site-packages/sqlalchemy/pool/base.py", line 894, in _checkout
    fairy = _ConnectionRecord.checkout(pool)
  File "/home/airflow/.local/lib/python3.8/site-packages/sqlalchemy/pool/base.py", line 493, in checkout
    rec = pool._do_get()
  File "/home/airflow/.local/lib/python3.8/site-packages/sqlalchemy/pool/impl.py", line 256, in _do_get
    return self._create_connection()
  File "/home/airflow/.local/lib/python3.8/site-packages/sqlalchemy/pool/base.py", line 273, in _create_connection
    return _ConnectionRecord(self)
  File "/home/airflow/.local/lib/python3.8/site-packages/sqlalchemy/pool/base.py", line 388, in __init__
    self.__connect()
  File "/home/airflow/.local/lib/python3.8/site-packages/sqlalchemy/pool/base.py", line 691, in __connect
    pool.logger.debug("Error on connect(): %s", e)
  File "/home/airflow/.local/lib/python3.8/site-packages/sqlalchemy/util/langhelpers.py", line 70, in __exit__
    compat.raise_(
  File "/home/airflow/.local/lib/python3.8/site-packages/sqlalchemy/util/compat.py", line 211, in raise_
    raise exception
  File "/home/airflow/.local/lib/python3.8/site-packages/sqlalchemy/pool/base.py", line 686, in __connect
    self.dbapi_connection = connection = pool._invoke_creator(self)
  File "/home/airflow/.local/lib/python3.8/site-packages/sqlalchemy/engine/create.py", line 574, in connect
    return dialect.connect(*cargs, **cparams)
  File "/home/airflow/.local/lib/python3.8/site-packages/sqlalchemy/engine/default.py", line 598, in connect
    return self.dbapi.connect(*cargs, **cparams)
  File "/home/airflow/.local/lib/python3.8/site-packages/psycopg2/__init__.py", line 122, in connect
    conn = _connect(dsn, connection_factory=connection_factory, **kwasync)
psycopg2.OperationalError: connection to server at "postgres" (172.19.0.5), port 5432 failed: server closed the connection unexpectedly
	This probably means the server terminated abnormally
	before or while processing the request.


The above exception was the direct cause of the following exception:

Traceback (most recent call last):
  File "/home/airflow/.local/lib/python3.8/site-packages/airflow/jobs/job.py", line 215, in heartbeat
    heartbeat_callback(session)
  File "/home/airflow/.local/lib/python3.8/site-packages/airflow/utils/session.py", line 74, in wrapper
    return func(*args, **kwargs)
  File "/home/airflow/.local/lib/python3.8/site-packages/airflow/jobs/local_task_job_runner.py", line 246, in heartbeat_callback
    self.task_instance.refresh_from_db()
  File "/home/airflow/.local/lib/python3.8/site-packages/airflow/utils/session.py", line 77, in wrapper
    return func(*args, session=session, **kwargs)
  File "/home/airflow/.local/lib/python3.8/site-packages/airflow/models/taskinstance.py", line 864, in refresh_from_db
    ti = qry.one_or_none()
  File "/home/airflow/.local/lib/python3.8/site-packages/sqlalchemy/orm/query.py", line 2850, in one_or_none
    return self._iter().one_or_none()
  File "/home/airflow/.local/lib/python3.8/site-packages/sqlalchemy/orm/query.py", line 2916, in _iter
    result = self.session.execute(
  File "/home/airflow/.local/lib/python3.8/site-packages/sqlalchemy/orm/session.py", line 1716, in execute
    conn = self._connection_for_bind(bind)
  File "/home/airflow/.local/lib/python3.8/site-packages/sqlalchemy/orm/session.py", line 1555, in _connection_for_bind
    return self._transaction._connection_for_bind(
  File "/home/airflow/.local/lib/python3.8/site-packages/sqlalchemy/orm/session.py", line 750, in _connection_for_bind
    conn = bind.connect()
  File "/home/airflow/.local/lib/python3.8/site-packages/sqlalchemy/future/engine.py", line 406, in connect
    return super(Engine, self).connect()
  File "/home/airflow/.local/lib/python3.8/site-packages/sqlalchemy/engine/base.py", line 3325, in connect
    return self._connection_cls(self, close_with_result=close_with_result)
  File "/home/airflow/.local/lib/python3.8/site-packages/sqlalchemy/engine/base.py", line 96, in __init__
    else engine.raw_connection()
  File "/home/airflow/.local/lib/python3.8/site-packages/sqlalchemy/engine/base.py", line 3404, in raw_connection
    return self._wrap_pool_connect(self.pool.connect, _connection)
  File "/home/airflow/.local/lib/python3.8/site-packages/sqlalchemy/engine/base.py", line 3374, in _wrap_pool_connect
    Connection._handle_dbapi_exception_noconnection(
  File "/home/airflow/.local/lib/python3.8/site-packages/sqlalchemy/engine/base.py", line 2208, in _handle_dbapi_exception_noconnection
    util.raise_(
  File "/home/airflow/.local/lib/python3.8/site-packages/sqlalchemy/util/compat.py", line 211, in raise_
    raise exception
  File "/home/airflow/.local/lib/python3.8/site-packages/sqlalchemy/engine/base.py", line 3371, in _wrap_pool_connect
    return fn()
  File "/home/airflow/.local/lib/python3.8/site-packages/sqlalchemy/pool/base.py", line 327, in connect
    return _ConnectionFairy._checkout(self)
  File "/home/airflow/.local/lib/python3.8/site-packages/sqlalchemy/pool/base.py", line 894, in _checkout
    fairy = _ConnectionRecord.checkout(pool)
  File "/home/airflow/.local/lib/python3.8/site-packages/sqlalchemy/pool/base.py", line 493, in checkout
    rec = pool._do_get()
  File "/home/airflow/.local/lib/python3.8/site-packages/sqlalchemy/pool/impl.py", line 256, in _do_get
    return self._create_connection()
  File "/home/airflow/.local/lib/python3.8/site-packages/sqlalchemy/pool/base.py", line 273, in _create_connection
    return _ConnectionRecord(self)
  File "/home/airflow/.local/lib/python3.8/site-packages/sqlalchemy/pool/base.py", line 388, in __init__
    self.__connect()
  File "/home/airflow/.local/lib/python3.8/site-packages/sqlalchemy/pool/base.py", line 691, in __connect
    pool.logger.debug("Error on connect(): %s", e)
  File "/home/airflow/.local/lib/python3.8/site-packages/sqlalchemy/util/langhelpers.py", line 70, in __exit__
    compat.raise_(
  File "/home/airflow/.local/lib/python3.8/site-packages/sqlalchemy/util/compat.py", line 211, in raise_
    raise exception
  File "/home/airflow/.local/lib/python3.8/site-packages/sqlalchemy/pool/base.py", line 686, in __connect
    self.dbapi_connection = connection = pool._invoke_creator(self)
  File "/home/airflow/.local/lib/python3.8/site-packages/sqlalchemy/engine/create.py", line 574, in connect
    return dialect.connect(*cargs, **cparams)
  File "/home/airflow/.local/lib/python3.8/site-packages/sqlalchemy/engine/default.py", line 598, in connect
    return self.dbapi.connect(*cargs, **cparams)
  File "/home/airflow/.local/lib/python3.8/site-packages/psycopg2/__init__.py", line 122, in connect
    conn = _connect(dsn, connection_factory=connection_factory, **kwasync)
sqlalchemy.exc.OperationalError: (psycopg2.OperationalError) connection to server at "postgres" (172.19.0.5), port 5432 failed: server closed the connection unexpectedly
	This probably means the server terminated abnormally
	before or while processing the request.

(Background on this error at: https://sqlalche.me/e/14/e3q8)
[2025-05-05T10:10:02.115+0000] {local_task_job_runner.py:115} ERROR - Received SIGTERM. Terminating subprocesses
